Workbook

Sheet テストエビデンス作成観点
B2: テストエビデンス作成時の観点
B4: 分類：全体
B5: No | D5: 確認内容
B6: =ROW()-4 -> 2 | D6: 全シート、カーソルをA1セルに置くこと
B7: =ROW()-4 -> 3 | D7: 表紙のシートで保存をすること
B8: =ROW()-4 -> 4 | D8: 全シート、表示倍率は100%にすること
B9: =ROW()-4 -> 5 | D9: 全シート、ヘッダー部分が文字化けしていないこと（#NAME?になっていないこと）
B10: =ROW()-4 -> 6 | D10: 全シート、ヘッダー部分が外部ファイルを参照していないこと
B11: =ROW()-4 -> 7 | D11: 文字フォントが一律、MSPゴシックとなっていること
B12: =ROW()-4 -> 8 | D12: 下記シート以外のシートが存在しないこと。※下記シートは作成すること ・表紙 ・更新履歴 ・画面詳細 ・イベント処理
B13: =ROW()-4 -> 9 | D13: 不要な書式（塗りつぶし）や過分な行は削除すること。不要な行は削除し、印刷範囲を狭めること
B14: =ROW()-4 -> 10 | D14: 修正箇所の文字色を赤色にしていること
B15: =ROW()-4 -> 11
B16: 分類：表紙
B17: 1 | D17: 表紙の作成者に、新規作成者の名前を記載すること
B18: =B17+1 -> 2
B19: 分類：更新履歴
B20: 1 | D20: バージョンを記載すること ※レビュー完成時にv1.0。その後、修正するごとに0.1あげていくこと
B21: =B20+1 -> 2 | D21: 章番号を記載すること ※番号となっているが、修正したシート名
B22: =B21+1 -> 3 | D22: 更新内容を記載すること
B23: =B22+1 -> 4 | D23: 作成者／更新者を記載すること
B24: =B23+1 -> 5 | D24: 内容欄に、修正対応を行ったTaskNoを記載していること (例)Task.999：○○○ボタンを新規で追加
B25: =B24+1 -> 6
B26: 分類：画面詳細（画面イメージ）
B27: 1 | D27: シート名は画面詳細（画面イメージ）であること
B28: =B27+1 -> 2 | D28: テスト仕様書のNoを記載していること
B29: =B28+1 -> 3 | D29: 確認に必要な画面イメージのスクリーンショットを全て取得していること
B30: =B29+1 -> 4
B31: 分類：画面詳細（画面表示項目）
B32: 1 | D32: シート名は画面詳細（画面表示項目）であること
B33: =B32+1 -> 2 | D33: テスト仕様書のNoを記載していること
B34: =B33+1 -> 3 | D34: 確認に必要な画面イメージのスクリーンショットを全て取得していること
B35: =B34+1 -> 4
B36: 分類：画面詳細（入力パラメータ）
B37: 1 | D37: シート名は画面詳細（入力パラメータ）であること
B38: =B37+1 -> 2 | D38: テスト仕様書のNoを記載していること
B39: =B38+1 -> 3 | D39: 確認に必要な画面イメージのスクリーンショットを全て取得していること
B40: =B39+1 -> 4 | D40: イベント実行前後の画面スクリーンショットを取得していること
B41: =B40+1 -> 5 | D41: 入力値など、画面スクリーンショットだけではわからないものについては吹き出しで記載していること
B42: =B41+1 -> 6
...

Sheet 表紙
O9: LMS学習管理システム
O10: 体験型Java研修
S12: エビデンス 画面レイアウト設計
S13: Task.29 勤怠管理直接変更画面
X17: ="第"&TEXT(MAX(更新履歴!A8:I31),"#0.0")&"版" -> 第1.0版 | AA17: =MAX(更新履歴!J8:Q31) -> 46038
U20: 作成者 | Z20: 審査者 | AE20: 承認者
U21: 大嶋悠暉

Sheet 更新履歴
A1: プロジェクト名 | J1: システム名 | R1: =表紙!S12 -> エビデンス 画面レイアウト設計 | AJ1: 作成者 | AO1: 作成日 | AT1: 更新者 | AY1: 更新日
A2: =表紙!O10 -> 体験型Java研修 | J2: =表紙!O9 -> LMS学習管理システム | R2: =表紙!S13 -> Task.29 勤怠管理直接変更画面 | AJ2: 上村 | AO2: 44295
A5: バージョン | J5: 日付 | R5: 章番号 | V5: 内容 | AT5: 作成者 / 更新者
A8: 1 | J8: 46038 | R8: 章全体 | V8: tbodyタグにスクロールバーの追加 | AT8: 大嶋悠暉

Sheet 画面詳細（画面イメージ）
A2: （画面mock） | M2: （開発画面）
I16: （開発画面）

Sheet イベント処理
A2: スクロール前 | M2: スクロール後
I16: （開発画面）
